Workbook

Sheet Dashboard
A1: Agentic Stability Framework v1.0 - Initial Public Release Dashboard
A2: Portfolio summary for Agentic Force, Enterprise Gravity, Stability Margin, and governance readiness
A4: Metric | B4: Value | D4: Orbit | E4: Count | F4: Default Action
A5: Total Agents | B5: =COUNTA(Assessment!A5:A104) -> 5 | D5: Stable Orbit | E5: =COUNTIF(Assessment!AH5:AH104,"Stable Orbit") -> 1 | F5: Scale with monitoring
A6: Average AFI | B6: =IFERROR(AVERAGE(Assessment!U5:U104),"") -> 61.714286 | D6: Controlled Orbit | E6: =COUNTIF(Assessment!AH5:AH104,"Controlled Orbit") -> 0 | F6: Proceed with controls
A7: Average EGI | B7: =IFERROR(AVERAGE(Assessment!V5:V104),"") -> 66.857143 | D7: Edge Orbit | E7: =COUNTIF(Assessment!AH5:AH104,"Edge Orbit") -> 3 | F7: Pilot / limited production
A8: Average SMI | B8: =IFERROR(AVERAGE(Assessment!W5:W104),"") -> 5.1428571 | D8: Unstable Orbit | E8: =COUNTIF(Assessment!AH5:AH104,"Unstable Orbit") -> 1 | F8: Control uplift required
A9: Negative SMI Agents | B9: =COUNTIF(Assessment!W5:W104,"<0") -> 2 | D9: Critical Orbit | E9: =COUNTIF(Assessment!AH5:AH104,"Critical Orbit") -> 0 | F9: Do not deploy
A10: ABOM Missing | B10: =COUNTIF(Assessment!Z5:Z104,"No") -> 2
A11: Threat Model Required | B11: =COUNTIF(Assessment!AA5:AA104,"Yes") -> 4
A12: Risk Acceptance Required | B12: =COUNTIF(Assessment!AB5:AB104,"Yes") -> 2
A13: Capped by Rule | B13: =COUNTIF(Assessment!AF5:AF104,"<>None")-COUNTBLANK(Assessment!AF5:AF104) -> 4
A15: Agent Snapshot
A16: Agent | B16: Domain | C16: AFI | D16: EGI | E16: SMI | F16: Final Orbit | G16: Rule Fired | H16: Next Uplift
A17: =IF(Assessment!$A5="","",Assessment!A5) -> Documentation Assistant | B17: =IF(Assessment!$A5="","",Assessment!B5) -> Knowledge / Documentation | C17: =IF(Assessment!$A5="","",Assessment!U5) -> 20 | D17: =IF(Assessment!$A5="","",Assessment!V5) -> 71.428571 | E17: =IF(Assessment!$A5="","",Assessment!W5) -> 51.428571 | F17: =IF(Assessment!$A5="","",Assessment!AH5) -> Stable Orbit | G17: =IF(Assessment!$A5="","",Assessment!AG5) -> - | H17: =IF(Assessment!$A5="","",Assessment!AE5) -> Add pre-execution and runtime policy checks; externalize policy decisions where practical.
A18: =IF(Assessment!$A6="","",Assessment!A6) -> Client-Request Automation Agent | B18: =IF(Assessment!$A6="","",Assessment!B6) -> Financial Operations | C18: =IF(Assessment!$A6="","",Assessment!U6) -> 60 | D18: =IF(Assessment!$A6="","",Assessment!V6) -> 65.714286 | E18: =IF(Assessment!$A6="","",Assessment!W6) -> 5.7142857 | F18: =IF(Assessment!$A6="","",Assessment!AH6) -> Edge Orbit | G18: =IF(Assessment!$A6="","",Assessment!AG6) -> R3 evidence tier 3<4; | H18: =IF(Assessment!$A6="","",Assessment!AE6) -> Add scenario tests, red-team tests, runtime evaluation, drift monitoring, and outcome validation.
A19: =IF(Assessment!$A7="","",Assessment!A7) -> Kubernetes Deployment Agent | B19: =IF(Assessment!$A7="","",Assessment!B7) -> Software Delivery | C19: =IF(Assessment!$A7="","",Assessment!U7) -> 65.714286 | D19: =IF(Assessment!$A7="","",Assessment!V7) -> 65.714286 | E19: =IF(Assessment!$A7="","",Assessment!W7) -> 0 | F19: =IF(Assessment!$A7="","",Assessment!AH7) -> Edge Orbit | G19: =IF(Assessment!$A7="","",Assessment!AG7) -> R1 concentrated force; R3 evidence tier 3<4; | H19: =IF(Assessment!$A7="","",Assessment!AE7) -> Add scenario tests, red-team tests, runtime evaluation, drift monitoring, and outcome validation.
A20: =IF(Assessment!$A8="","",Assessment!A8) -> Multi-Agent SDLC Workflow | B20: =IF(Assessment!$A8="","",Assessment!B8) -> Multi-Agent SDLC | C20: =IF(Assessment!$A8="","",Assessment!U8) -> 74.285714 | D20: =IF(Assessment!$A8="","",Assessment!V8) -> 62.857143 | E20: =IF(Assessment!$A8="","",Assessment!W8) -> -11.428571 | F20: =IF(Assessment!$A8="","",Assessment!AH8) -> Edge Orbit | G20: =IF(Assessment!$A8="","",Assessment!AG8) -> R1 concentrated force; | H20: =IF(Assessment!$A8="","",Assessment!AE8) -> Assign dedicated workload identity; remove shared credentials; add ownership metadata.
A21: =IF(Assessment!$A9="","",Assessment!A9) -> Autonomous Production Remediation Agent | B21: =IF(Assessment!$A9="","",Assessment!B9) -> Cloud / Infrastructure | C21: =IF(Assessment!$A9="","",Assessment!U9) -> 88.571429 | D21: =IF(Assessment!$A9="","",Assessment!V9) -> 68.571429 | E21: =IF(Assessment!$A9="","",Assessment!W9) -> -20 | F21: =IF(Assessment!$A9="","",Assessment!AH9) -> Unstable Orbit | G21: =IF(Assessment!$A9="","",Assessment!AG9) -> R1 concentrated force; R3 evidence tier 3<4; | H21: =IF(Assessment!$A9="","",Assessment!AE9) -> Add scenario tests, red-team tests, runtime evaluation, drift monitoring, and outcome validation.
A22: =IF(Assessment!$A10="","",Assessment!A10) | B22: =IF(Assessment!$A10="","",Assessment!B10) | C22: =IF(Assessment!$A10="","",Assessment!U10) | D22: =IF(Assessment!$A10="","",Assessment!V10) | E22: =IF(Assessment!$A10="","",Assessment!W10) | F22: =IF(Assessment!$A10="","",Assessment!AH10) | G22: =IF(Assessment!$A10="","",Assessment!AG10) | H22: =IF(Assessment!$A10="","",Assessment!AE10)
A23: =IF(Assessment!$A11="","",Assessment!A11) | B23: =IF(Assessment!$A11="","",Assessment!B11) | C23: =IF(Assessment!$A11="","",Assessment!U11) | D23: =IF(Assessment!$A11="","",Assessment!V11) | E23: =IF(Assessment!$A11="","",Assessment!W11) | F23: =IF(Assessment!$A11="","",Assessment!AH11) | G23: =IF(Assessment!$A11="","",Assessment!AG11) | H23: =IF(Assessment!$A11="","",Assessment!AE11)
A24: =IF(Assessment!$A12="","",Assessment!A12) | B24: =IF(Assessment!$A12="","",Assessment!B12) | C24: =IF(Assessment!$A12="","",Assessment!U12) | D24: =IF(Assessment!$A12="","",Assessment!V12) | E24: =IF(Assessment!$A12="","",Assessment!W12) | F24: =IF(Assessment!$A12="","",Assessment!AH12) | G24: =IF(Assessment!$A12="","",Assessment!AG12) | H24: =IF(Assessment!$A12="","",Assessment!AE12)
A25: =IF(Assessment!$A13="","",Assessment!A13) | B25: =IF(Assessment!$A13="","",Assessment!B13) | C25: =IF(Assessment!$A13="","",Assessment!U13) | D25: =IF(Assessment!$A13="","",Assessment!V13) | E25: =IF(Assessment!$A13="","",Assessment!W13) | F25: =IF(Assessment!$A13="","",Assessment!AH13) | G25: =IF(Assessment!$A13="","",Assessment!AG13) | H25: =IF(Assessment!$A13="","",Assessment!AE13)
A26: =IF(Assessment!$A14="","",Assessment!A14) | B26: =IF(Assessment!$A14="","",Assessment!B14) | C26: =IF(Assessment!$A14="","",Assessment!U14) | D26: =IF(Assessment!$A14="","",Assessment!V14) | E26: =IF(Assessment!$A14="","",Assessment!W14) | F26: =IF(Assessment!$A14="","",Assessment!AH14) | G26: =IF(Assessment!$A14="","",Assessment!AG14) | H26: =IF(Assessment!$A14="","",Assessment!AE14)
A27: =IF(Assessment!$A15="","",Assessment!A15) | B27: =IF(Assessment!$A15="","",Assessment!B15) | C27: =IF(Assessment!$A15="","",Assessment!U15) | D27: =IF(Assessment!$A15="","",Assessment!V15) | E27: =IF(Assessment!$A15="","",Assessment!W15) | F27: =IF(Assessment!$A15="","",Assessment!AH15) | G27: =IF(Assessment!$A15="","",Assessment!AG15) | H27: =IF(Assessment!$A15="","",Assessment!AE15)
A28: =IF(Assessment!$A16="","",Assessment!A16) | B28: =IF(Assessment!$A16="","",Assessment!B16) | C28: =IF(Assessment!$A16="","",Assessment!U16) | D28: =IF(Assessment!$A16="","",Assessment!V16) | E28: =IF(Assessment!$A16="","",Assessment!W16) | F28: =IF(Assessment!$A16="","",Assessment!AH16) | G28: =IF(Assessment!$A16="","",Assessment!AG16) | H28: =IF(Assessment!$A16="","",Assessment!AE16)
... A36: =IF(Assessment!$A24="","",Assessment!A24) | B36: =IF(Assessment!$A24="","",Assessment!B24) | C36: =IF(Assessment!$A24="","",Assessment!U24) | D36: =IF(Assessment!$A24="","",Assessment!V24) | E36: =IF(Assessment!$A24="","",Assessment!W24) | F36: =IF(Assessment!$A24="","",Assessment!AH24) | G36: =IF(Assessment!$A24="","",Assessment!AG24) | H36: =IF(Assessment!$A24="","",Assessment!AE24)

Sheet Assessment
A1: ASF Agentic System Instance Assessment v1.0 - Initial Public Release
A2: Enter force/gravity scores for the deployed agentic system instance. Formulas compute AFI, EGI, SMI, orbit, and action.
A4: Agent Name | B4: Domain Overlay | C4: Deployment Zone | D4: Scoring Mode | E4: Decision Autonomy | F4: Decision Velocity | G4: Operational Reach | H4: Operational Criticality | I4: Adaptability | J4: Collaboration Complexity | K4: Persistence and Memory | L4: Identity | M4: Authorization | N4: Policy Enforcement | O4: Observability | P4: Governance and Lifecycle | Q4: Recovery and Resilience | R4: Assurance and Evaluation | S4: Min Evidence Tier | T4: Evidence Warning | U4: AFI | V4: EGI | W4: SMI | X4: SMI Orbit | Y4: Deployment Decision | Z4: ABOM Complete | AA4: Threat Model Required | AB4: Risk Acceptance Required | AC4: Weakest Gravity | AD4: Highest Force | AE4: Next Control Uplift | AF4: Non-Compensatory Ceiling | AG4: Rule Fired | AH4: Final Orbit | AI4: Threat Model Completed | AJ4: Review Date
A5: Documentation Assistant | B5: Knowledge / Documentation | C5: Assisted Zone | D5: Basic | E5: 1 | F5: 1 | G5: 1 | H5: 1 | I5: 1 | J5: 1 | K5: 1 | L5: 4 | M5: 4 | N5: 3 | O5: 4 | P5: 4 | Q5: 3 | R5: 3 | S5: 3 | T5: =IF($A5="","",IF(AND(MAX(L5:R5)>3,S5<3),"Warning: EGI >3 needs Tier 3+ evidence",IF(AND(C5="Autonomous Operations Zone",S5<4),"Warning: Autonomous zone needs Tier 4 evidence","OK"))) -> OK | U5: =IF($A5="","",IF($D5="Basic",SUM(E5:K5)/35*100,SUMPRODUCT(E5:K5,INDEX('Weighted Scoring'!$B$5:$H$13,MATCH($B5,'Weighted Scoring'!$A$5:$A$13,0),0))/SUMPRODUCT(5,INDEX('Weighted Scoring'!$B$5:$H$13,MATCH($B5,'Weighted Scoring'!$A$5:$A$13,0),0))*100)) -> 20 | V5: =IF($A5="","",IF($D5="Basic",SUM(L5:R5)/35*100,SUMPRODUCT(L5:R5,INDEX('Weighted Scoring'!$I$5:$O$13,MATCH($B5,'Weighted Scoring'!$A$5:$A$13,0),0))/SUMPRODUCT(5,INDEX('Weighted Scoring'!$I$5:$O$13,MATCH($B5,'Weighted Scoring'!$A$5:$A$13,0),0))*100)) -> 71.428571 | W5: =IF($A5="","",V5-U5) -> 51.428571 | X5: =IF($A5="","",IF(W5>=40,"Stable Orbit",IF(W5>=15,"Controlled Orbit",IF(W5>=-14,"Edge Orbit",IF(W5>=-39,"Unstable Orbit","Critical Orbit"))))) -> Stable Orbit | Y5: =IF($A5="","",INDEX('Deployment Gates'!$C$5:$C$9,MATCH(AH5,'Deployment Gates'!$A$5:$A$9,0))) -> Approved for scale with monitoring | Z5: Yes | AA5: =IF($A5="","",IF(OR(AH5="Edge Orbit",AH5="Unstable Orbit",AH5="Critical Orbit",H5>=4,G5>=4,E5>=4,J5>=4),"Yes","No")) -> No | AB5: =IF($A5="","",IF(W5<0,"Yes","No")) -> No | AC5: =IF($A5="","",INDEX($L$4:$R$4,1,MATCH(MIN(L5:R5),L5:R5,0))&IF(COUNTIF(L5:R5,MIN(L5:R5))>1," (+"&(COUNTIF(L5:R5,MIN(L5:R5))-1)&" tied)","")) -> Policy Enforcement (+2 tied) | AD5: =IF($A5="","",INDEX($E$4:$K$4,1,MATCH(MAX(E5:K5),E5:K5,0))&IF(COUNTIF(E5:K5,MAX(E5:K5))>1," (+"&(COUNTIF(E5:K5,MAX(E5:K5))-1)&" tied)","")) -> Decision Autonomy (+6 tied) | AE5: =IF($A5="","",INDEX('Control Uplift Planner'!$B$5:$B$11,MATCH(INDEX($L$4:$R$4,1,MATCH(MIN(L5:R5),L5:R5,0)),'Control Uplift Planner'!$A$5:$A$11,0))) -> Add pre-execution and runtime policy checks; externalize policy decisions where practical. | AF5: =IF($A5="","",IF(MIN(IF(AND(E5>=4,H5>=4),3,9),IF(AND(OR(C5="Governed Operations Zone",C5="Autonomous Operations Zone"),E5>=3),IF(MIN(L5:N5)=0,2,IF(MIN(L5:N5)=1,3,9)),9),IF(AND(OR(C5="Governed Operations Zone",C5="Autonomous Operations Zone"),S5<4),3,9))=9,"None",IF(MIN(IF(AND(E5>=4,H5>=4),3,9),IF(AND(OR(C5="Governed Operations Zone",C5="Autonomous Operations Zone"),E5>=3),IF(MIN(L5:N5)=0,2,IF(MIN(L5:N5)=1,3,9)),9),IF(AND(OR(C5="Governed Operations Zone",C5="Autonomous Operations Zone"),S5<4),3,9))=1,"Critical Orbit",IF(MIN(IF(AND(E5>=4,H5>=4),3,9),IF(AND(OR(C5="Governed Operations Zone",C5="Autonomous Operations Zone"),E5>=3),IF(MIN(L5:N5)=0,2,IF(MIN(L5:N5)=1,3,9)),9),IF(AND(OR(C5="Governed Operations Zone",C5="Autonomous Operations Zone"),S5<4),3,9))=2,"Unstable Orbit","Edge Orbit")))) -> None | AG5: =IF($A5="","",IF(IF(AND(E5>=4,H5>=4),"R1 concentrated force; ","")&IF(AND(OR(C5="Governed Operations Zone",C5="Autonomous Operations Zone"),E5>=3,MIN(L5:N5)<=1),"R2 mandatory control "&INDEX($L$4:$N$4,1,MATCH(MIN(L5:N5),L5:N5,0))&"="&MIN(L5:N5)&"; ","")&IF(AND(OR(C5="Governed Operations Zone",C5="Autonomous Operations Zone"),S5<4),"R3 evidence tier "&S5&"<4; ","")="","-",IF(AND(E5>=4,H5>=4),"R1 concentrated force; ","")&IF(AND(OR(C5="Governed Operations Zone",C5="Autonomous Operations Zone"),E5>=3,MIN(L5:N5)<=1),"R2 mandatory control "&INDEX($L$4:$N$4,1,MATCH(MIN(L5:N5),L5:N5,0))&"="&MIN(L5:N5)&"; ","")&IF(AND(OR(C5="Governed Operations Zone",C5="Autonomous Operations Zone"),S5<4),"R3 evidence tier "&S5&"<4; ",""))) -> - | AH5: =IF($A5="","",IF(MIN(IF(X5="Critical Orbit",1,IF(X5="Unstable Orbit",2,IF(X5="Edge Orbit",3,IF(X5="Controlled Orbit",4,5)))),IF(AF5="None",9,IF(AF5="Critical Orbit",1,IF(AF5="Unstable Orbit",2,IF(AF5="Edge Orbit",3,IF(AF5="Controlled Orbit",4,5))))))=1,"Critical Orbit",IF(MIN(IF(X5="Critical Orbit",1,IF(X5="Unstable Orbit",2,IF(X5="Edge Orbit",3,IF(X5="Controlled Orbit",4,5)))),IF(AF5="None",9,IF(AF5="Critical Orbit",1,IF(AF5="Unstable Orbit",2,IF(AF5="Edge Orbit",3,IF(AF5="Controlled Orbit",4,5))))))=2,"Unstable Orbit",IF(MIN(IF(X5="Critical Orbit",1,IF(X5="Unstable Orbit",2,IF(X5="Edge Orbit",3,IF(X5="Controlled Orbit",4,5)))),IF(AF5="None",9,IF(AF5="Critical Orbit",1,IF(AF5="Unstable Orbit",2,IF(AF5="Edge Orbit",3,IF(AF5="Controlled Orbit",4,5))))))=3,"Edge Orbit",IF(MIN(IF(X5="Critical Orbit",1,IF(X5="Unstable Orbit",2,IF(X5="Edge Orbit",3,IF(X5="Controlled Orbit",4,5)))),IF(AF5="None",9,IF(AF5="Critical Orbit",1,IF(AF5="Unstable Orbit",2,IF(AF5="Edge Orbit",3,IF(AF5="Controlled Orbit",4,5))))))=4,"Controlled Orbit","Stable Orbit"))))) -> Stable Orbit | AJ5: 2026-09-30
A6: Client-Request Automation Agent | B6: Financial Operations | C6: Governed Operations Zone | D6: Basic | E6: 3 | F6: 3 | G6: 3 | H6: 5 | I6: 3 | J6: 2 | K6: 2 | L6: 4 | M6: 4 | N6: 4 | O6: 3 | P6: 3 | Q6: 3 | R6: 2 | S6: 3 | T6: =IF($A6="","",IF(AND(MAX(L6:R6)>3,S6<3),"Warning: EGI >3 needs Tier 3+ evidence",IF(AND(C6="Autonomous Operations Zone",S6<4),"Warning: Autonomous zone needs Tier 4 evidence","OK"))) -> OK | U6: =IF($A6="","",IF($D6="Basic",SUM(E6:K6)/35*100,SUMPRODUCT(E6:K6,INDEX('Weighted Scoring'!$B$5:$H$13,MATCH($B6,'Weighted Scoring'!$A$5:$A$13,0),0))/SUMPRODUCT(5,INDEX('Weighted Scoring'!$B$5:$H$13,MATCH($B6,'Weighted Scoring'!$A$5:$A$13,0),0))*100)) -> 60 | V6: =IF($A6="","",IF($D6="Basic",SUM(L6:R6)/35*100,SUMPRODUCT(L6:R6,INDEX('Weighted Scoring'!$I$5:$O$13,MATCH($B6,'Weighted Scoring'!$A$5:$A$13,0),0))/SUMPRODUCT(5,INDEX('Weighted Scoring'!$I$5:$O$13,MATCH($B6,'Weighted Scoring'!$A$5:$A$13,0),0))*100)) -> 65.714286 | W6: =IF($A6="","",V6-U6) -> 5.7142857 | X6: =IF($A6="","",IF(W6>=40,"Stable Orbit",IF(W6>=15,"Controlled Orbit",IF(W6>=-14,"Edge Orbit",IF(W6>=-39,"Unstable Orbit","Critical Orbit"))))) -> Edge Orbit | Y6: =IF($A6="","",INDEX('Deployment Gates'!$C$5:$C$9,MATCH(AH6,'Deployment Gates'!$A$5:$A$9,0))) -> Pilot, sandbox, or limited production only | Z6: Yes | AA6: =IF($A6="","",IF(OR(AH6="Edge Orbit",AH6="Unstable Orbit",AH6="Critical Orbit",H6>=4,G6>=4,E6>=4,J6>=4),"Yes","No")) -> Yes | AB6: =IF($A6="","",IF(W6<0,"Yes","No")) -> No | AC6: =IF($A6="","",INDEX($L$4:$R$4,1,MATCH(MIN(L6:R6),L6:R6,0))&IF(COUNTIF(L6:R6,MIN(L6:R6))>1," (+"&(COUNTIF(L6:R6,MIN(L6:R6))-1)&" tied)","")) -> Assurance and Evaluation | AD6: =IF($A6="","",INDEX($E$4:$K$4,1,MATCH(MAX(E6:K6),E6:K6,0))&IF(COUNTIF(E6:K6,MAX(E6:K6))>1," (+"&(COUNTIF(E6:K6,MAX(E6:K6))-1)&" tied)","")) -> Operational Criticality | AE6: =IF($A6="","",INDEX('Control Uplift Planner'!$B$5:$B$11,MATCH(INDEX($L$4:$R$4,1,MATCH(MIN(L6:R6),L6:R6,0)),'Control Uplift Planner'!$A$5:$A$11,0))) -> Add scenario tests, red-team tests, runtime evaluation, drift monitoring, and outcome validation. | AF6: =IF($A6="","",IF(MIN(IF(AND(E6>=4,H6>=4),3,9),IF(AND(OR(C6="Governed Operations Zone",C6="Autonomous Operations Zone"),E6>=3),IF(MIN(L6:N6)=0,2,IF(MIN(L6:N6)=1,3,9)),9),IF(AND(OR(C6="Governed Operations Zone",C6="Autonomous Operations Zone"),S6<4),3,9))=9,"None",IF(MIN(IF(AND(E6>=4,H6>=4),3,9),IF(AND(OR(C6="Governed Operations Zone",C6="Autonomous Operations Zone"),E6>=3),IF(MIN(L6:N6)=0,2,IF(MIN(L6:N6)=1,3,9)),9),IF(AND(OR(C6="Governed Operations Zone",C6="Autonomous Operations Zone"),S6<4),3,9))=1,"Critical Orbit",IF(MIN(IF(AND(E6>=4,H6>=4),3,9),IF(AND(OR(C6="Governed Operations Zone",C6="Autonomous Operations Zone"),E6>=3),IF(MIN(L6:N6)=0,2,IF(MIN(L6:N6)=1,3,9)),9),IF(AND(OR(C6="Governed Operations Zone",C6="Autonomous Operations Zone"),S6<4),3,9))=2,"Unstable Orbit","Edge Orbit")))) -> Edge Orbit | AG6: =IF($A6="","",IF(IF(AND(E6>=4,H6>=4),"R1 concentrated force; ","")&IF(AND(OR(C6="Governed Operations Zone",C6="Autonomous Operations Zone"),E6>=3,MIN(L6:N6)<=1),"R2 mandatory control "&INDEX($L$4:$N$4,1,MATCH(MIN(L6:N6),L6:N6,0))&"="&MIN(L6:N6)&"; ","")&IF(AND(OR(C6="Governed Operations Zone",C6="Autonomous Operations Zone"),S6<4),"R3 evidence tier "&S6&"<4; ","")="","-",IF(AND(E6>=4,H6>=4),"R1 concentrated force; ","")&IF(AND(OR(C6="Governed Operations Zone",C6="Autonomous Operations Zone"),E6>=3,MIN(L6:N6)<=1),"R2 mandatory control "&INDEX($L$4:$N$4,1,MATCH(MIN(L6:N6),L6:N6,0))&"="&MIN(L6:N6)&"; ","")&IF(AND(OR(C6="Governed Operations Zone",C6="Autonomous Operations Zone"),S6<4),"R3 evidence tier "&S6&"<4; ",""))) -> R3 evidence tier 3<4; | AH6: =IF($A6="","",IF(MIN(IF(X6="Critical Orbit",1,IF(X6="Unstable Orbit",2,IF(X6="Edge Orbit",3,IF(X6="Controlled Orbit",4,5)))),IF(AF6="None",9,IF(AF6="Critical Orbit",1,IF(AF6="Unstable Orbit",2,IF(AF6="Edge Orbit",3,IF(AF6="Controlled Orbit",4,5))))))=1,"Critical Orbit",IF(MIN(IF(X6="Critical Orbit",1,IF(X6="Unstable Orbit",2,IF(X6="Edge Orbit",3,IF(X6="Controlled Orbit",4,5)))),IF(AF6="None",9,IF(AF6="Critical Orbit",1,IF(AF6="Unstable Orbit",2,IF(AF6="Edge Orbit",3,IF(AF6="Controlled Orbit",4,5))))))=2,"Unstable Orbit",IF(MIN(IF(X6="Critical Orbit",1,IF(X6="Unstable Orbit",2,IF(X6="Edge Orbit",3,IF(X6="Controlled Orbit",4,5)))),IF(AF6="None",9,IF(AF6="Critical Orbit",1,IF(AF6="Unstable Orbit",2,IF(AF6="Edge Orbit",3,IF(AF6="Controlled Orbit",4,5))))))=3,"Edge Orbit",IF(MIN(IF(X6="Critical Orbit",1,IF(X6="Unstable Orbit",2,IF(X6="Edge Orbit",3,IF(X6="Controlled Orbit",4,5)))),IF(AF6="None",9,IF(AF6="Critical Orbit",1,IF(AF6="Unstable Orbit",2,IF(AF6="Edge Orbit",3,IF(AF6="Controlled Orbit",4,5))))))=4,"Controlled Orbit","Stable Orbit"))))) -> Edge Orbit | AJ6: 2026-09-30
A7: Kubernetes Deployment Agent | B7: Software Delivery | C7: Governed Operations Zone | D7: Basic | E7: 4 | F7: 3 | G7: 4 | H7: 4 | I7: 3 | J7: 2 | K7: 3 | L7: 4 | M7: 3 | N7: 4 | O7: 3 | P7: 3 | Q7: 4 | R7: 2 | S7: 3 | T7: =IF($A7="","",IF(AND(MAX(L7:R7)>3,S7<3),"Warning: EGI >3 needs Tier 3+ evidence",IF(AND(C7="Autonomous Operations Zone",S7<4),"Warning: Autonomous zone needs Tier 4 evidence","OK"))) -> OK | U7: =IF($A7="","",IF($D7="Basic",SUM(E7:K7)/35*100,SUMPRODUCT(E7:K7,INDEX('Weighted Scoring'!$B$5:$H$13,MATCH($B7,'Weighted Scoring'!$A$5:$A$13,0),0))/SUMPRODUCT(5,INDEX('Weighted Scoring'!$B$5:$H$13,MATCH($B7,'Weighted Scoring'!$A$5:$A$13,0),0))*100)) -> 65.714286 | V7: =IF($A7="","",IF($D7="Basic",SUM(L7:R7)/35*100,SUMPRODUCT(L7:R7,INDEX('Weighted Scoring'!$I$5:$O$13,MATCH($B7,'Weighted Scoring'!$A$5:$A$13,0),0))/SUMPRODUCT(5,INDEX('Weighted Scoring'!$I$5:$O$13,MATCH($B7,'Weighted Scoring'!$A$5:$A$13,0),0))*100)) -> 65.714286 | W7: =IF($A7="","",V7-U7) -> 0 | X7: =IF($A7="","",IF(W7>=40,"Stable Orbit",IF(W7>=15,"Controlled Orbit",IF(W7>=-14,"Edge Orbit",IF(W7>=-39,"Unstable Orbit","Critical Orbit"))))) -> Edge Orbit | Y7: =IF($A7="","",INDEX('Deployment Gates'!$C$5:$C$9,MATCH(AH7,'Deployment Gates'!$A$5:$A$9,0))) -> Pilot, sandbox, or limited production only | Z7: Yes | AA7: =IF($A7="","",IF(OR(AH7="Edge Orbit",AH7="Unstable Orbit",AH7="Critical Orbit",H7>=4,G7>=4,E7>=4,J7>=4),"Yes","No")) -> Yes | AB7: =IF($A7="","",IF(W7<0,"Yes","No")) -> No | AC7: =IF($A7="","",INDEX($L$4:$R$4,1,MATCH(MIN(L7:R7),L7:R7,0))&IF(COUNTIF(L7:R7,MIN(L7:R7))>1," (+"&(COUNTIF(L7:R7,MIN(L7:R7))-1)&" tied)","")) -> Assurance and Evaluation | AD7: =IF($A7="","",INDEX($E$4:$K$4,1,MATCH(MAX(E7:K7),E7:K7,0))&IF(COUNTIF(E7:K7,MAX(E7:K7))>1," (+"&(COUNTIF(E7:K7,MAX(E7:K7))-1)&" tied)","")) -> Decision Autonomy (+2 tied) | AE7: =IF($A7="","",INDEX('Control Uplift Planner'!$B$5:$B$11,MATCH(INDEX($L$4:$R$4,1,MATCH(MIN(L7:R7),L7:R7,0)),'Control Uplift Planner'!$A$5:$A$11,0))) -> Add scenario tests, red-team tests, runtime evaluation, drift monitoring, and outcome validation. | AF7: =IF($A7="","",IF(MIN(IF(AND(E7>=4,H7>=4),3,9),IF(AND(OR(C7="Governed Operations Zone",C7="Autonomous Operations Zone"),E7>=3),IF(MIN(L7:N7)=0,2,IF(MIN(L7:N7)=1,3,9)),9),IF(AND(OR(C7="Governed Operations Zone",C7="Autonomous Operations Zone"),S7<4),3,9))=9,"None",IF(MIN(IF(AND(E7>=4,H7>=4),3,9),IF(AND(OR(C7="Governed Operations Zone",C7="Autonomous Operations Zone"),E7>=3),IF(MIN(L7:N7)=0,2,IF(MIN(L7:N7)=1,3,9)),9),IF(AND(OR(C7="Governed Operations Zone",C7="Autonomous Operations Zone"),S7<4),3,9))=1,"Critical Orbit",IF(MIN(IF(AND(E7>=4,H7>=4),3,9),IF(AND(OR(C7="Governed Operations Zone",C7="Autonomous Operations Zone"),E7>=3),IF(MIN(L7:N7)=0,2,IF(MIN(L7:N7)=1,3,9)),9),IF(AND(OR(C7="Governed Operations Zone",C7="Autonomous Operations Zone"),S7<4),3,9))=2,"Unstable Orbit","Edge Orbit")))) -> Edge Orbit | AG7: =IF($A7="","",IF(IF(AND(E7>=4,H7>=4),"R1 concentrated force; ","")&IF(AND(OR(C7="Governed Operations Zone",C7="Autonomous Operations Zone"),E7>=3,MIN(L7:N7)<=1),"R2 mandatory control "&INDEX($L$4:$N$4,1,MATCH(MIN(L7:N7),L7:N7,0))&"="&MIN(L7:N7)&"; ","")&IF(AND(OR(C7="Governed Operations Zone",C7="Autonomous Operations Zone"),S7<4),"R3 evidence tier "&S7&"<4; ","")="","-",IF(AND(E7>=4,H7>=4),"R1 concentrated force; ","")&IF(AND(OR(C7="Governed Operations Zone",C7="Autonomous Operations Zone"),E7>=3,MIN(L7:N7)<=1),"R2 mandatory control "&INDEX($L$4:$N$4,1,MATCH(MIN(L7:N7),L7:N7,0))&"="&MIN(L7:N7)&"; ","")&IF(AND(OR(C7="Governed Operations Zone",C7="Autonomous Operations Zone"),S7<4),"R3 evidence tier "&S7&"<4; ",""))) -> R1 concentrated force; R3 evidence tier 3<4; | AH7: =IF($A7="","",IF(MIN(IF(X7="Critical Orbit",1,IF(X7="Unstable Orbit",2,IF(X7="Edge Orbit",3,IF(X7="Controlled Orbit",4,5)))),IF(AF7="None",9,IF(AF7="Critical Orbit",1,IF(AF7="Unstable Orbit",2,IF(AF7="Edge Orbit",3,IF(AF7="Controlled Orbit",4,5))))))=1,"Critical Orbit",IF(MIN(IF(X7="Critical Orbit",1,IF(X7="Unstable Orbit",2,IF(X7="Edge Orbit",3,IF(X7="Controlled Orbit",4,5)))),IF(AF7="None",9,IF(AF7="Critical Orbit",1,IF(AF7="Unstable Orbit",2,IF(AF7="Edge Orbit",3,IF(AF7="Controlled Orbit",4,5))))))=2,"Unstable Orbit",IF(MIN(IF(X7="Critical Orbit",1,IF(X7="Unstable Orbit",2,IF(X7="Edge Orbit",3,IF(X7="Controlled Orbit",4,5)))),IF(AF7="None",9,IF(AF7="Critical Orbit",1,IF(AF7="Unstable Orbit",2,IF(AF7="Edge Orbit",3,IF(AF7="Controlled Orbit",4,5))))))=3,"Edge Orbit",IF(MIN(IF(X7="Critical Orbit",1,IF(X7="Unstable Orbit",2,IF(X7="Edge Orbit",3,IF(X7="Controlled Orbit",4,5)))),IF(AF7="None",9,IF(AF7="Critical Orbit",1,IF(AF7="Unstable Orbit",2,IF(AF7="Edge Orbit",3,IF(AF7="Controlled Orbit",4,5))))))=4,"Controlled Orbit","Stable Orbit"))))) -> Edge Orbit | AJ7: 2026-08-31
A8: Multi-Agent SDLC Workflow | B8: Multi-Agent SDLC | C8: Assisted Zone | D8: Basic | E8: 4 | F8: 3 | G8: 4 | H8: 4 | I8: 4 | J8: 4 | K8: 3 | L8: 3 | M8: 3 | N8: 3 | O8: 4 | P8: 3 | Q8: 3 | R8: 3 | S8: 3 | T8: =IF($A8="","",IF(AND(MAX(L8:R8)>3,S8<3),"Warning: EGI >3 needs Tier 3+ evidence",IF(AND(C8="Autonomous Operations Zone",S8<4),"Warning: Autonomous zone needs Tier 4 evidence","OK"))) -> OK | U8: =IF($A8="","",IF($D8="Basic",SUM(E8:K8)/35*100,SUMPRODUCT(E8:K8,INDEX('Weighted Scoring'!$B$5:$H$13,MATCH($B8,'Weighted Scoring'!$A$5:$A$13,0),0))/SUMPRODUCT(5,INDEX('Weighted Scoring'!$B$5:$H$13,MATCH($B8,'Weighted Scoring'!$A$5:$A$13,0),0))*100)) -> 74.285714 | V8: =IF($A8="","",IF($D8="Basic",SUM(L8:R8)/35*100,SUMPRODUCT(L8:R8,INDEX('Weighted Scoring'!$I$5:$O$13,MATCH($B8,'Weighted Scoring'!$A$5:$A$13,0),0))/SUMPRODUCT(5,INDEX('Weighted Scoring'!$I$5:$O$13,MATCH($B8,'Weighted Scoring'!$A$5:$A$13,0),0))*100)) -> 62.857143 | W8: =IF($A8="","",V8-U8) -> -11.428571 | X8: =IF($A8="","",IF(W8>=40,"Stable Orbit",IF(W8>=15,"Controlled Orbit",IF(W8>=-14,"Edge Orbit",IF(W8>=-39,"Unstable Orbit","Critical Orbit"))))) -> Edge Orbit | Y8: =IF($A8="","",INDEX('Deployment Gates'!$C$5:$C$9,MATCH(AH8,'Deployment Gates'!$A$5:$A$9,0))) -> Pilot, sandbox, or limited production only | Z8: No | AA8: =IF($A8="","",IF(OR(AH8="Edge Orbit",AH8="Unstable Orbit",AH8="Critical Orbit",H8>=4,G8>=4,E8>=4,J8>=4),"Yes","No")) -> Yes | AB8: =IF($A8="","",IF(W8<0,"Yes","No")) -> Yes | AC8: =IF($A8="","",INDEX($L$4:$R$4,1,MATCH(MIN(L8:R8),L8:R8,0))&IF(COUNTIF(L8:R8,MIN(L8:R8))>1," (+"&(COUNTIF(L8:R8,MIN(L8:R8))-1)&" tied)","")) -> Identity (+5 tied) | AD8: =IF($A8="","",INDEX($E$4:$K$4,1,MATCH(MAX(E8:K8),E8:K8,0))&IF(COUNTIF(E8:K8,MAX(E8:K8))>1," (+"&(COUNTIF(E8:K8,MAX(E8:K8))-1)&" tied)","")) -> Decision Autonomy (+4 tied) | AE8: =IF($A8="","",INDEX('Control Uplift Planner'!$B$5:$B$11,MATCH(INDEX($L$4:$R$4,1,MATCH(MIN(L8:R8),L8:R8,0)),'Control Uplift Planner'!$A$5:$A$11,0))) -> Assign dedicated workload identity; remove shared credentials; add ownership metadata. | AF8: =IF($A8="","",IF(MIN(IF(AND(E8>=4,H8>=4),3,9),IF(AND(OR(C8="Governed Operations Zone",C8="Autonomous Operations Zone"),E8>=3),IF(MIN(L8:N8)=0,2,IF(MIN(L8:N8)=1,3,9)),9),IF(AND(OR(C8="Governed Operations Zone",C8="Autonomous Operations Zone"),S8<4),3,9))=9,"None",IF(MIN(IF(AND(E8>=4,H8>=4),3,9),IF(AND(OR(C8="Governed Operations Zone",C8="Autonomous Operations Zone"),E8>=3),IF(MIN(L8:N8)=0,2,IF(MIN(L8:N8)=1,3,9)),9),IF(AND(OR(C8="Governed Operations Zone",C8="Autonomous Operations Zone"),S8<4),3,9))=1,"Critical Orbit",IF(MIN(IF(AND(E8>=4,H8>=4),3,9),IF(AND(OR(C8="Governed Operations Zone",C8="Autonomous Operations Zone"),E8>=3),IF(MIN(L8:N8)=0,2,IF(MIN(L8:N8)=1,3,9)),9),IF(AND(OR(C8="Governed Operations Zone",C8="Autonomous Operations Zone"),S8<4),3,9))=2,"Unstable Orbit","Edge Orbit")))) -> Edge Orbit | AG8: =IF($A8="","",IF(IF(AND(E8>=4,H8>=4),"R1 concentrated force; ","")&IF(AND(OR(C8="Governed Operations Zone",C8="Autonomous Operations Zone"),E8>=3,MIN(L8:N8)<=1),"R2 mandatory control "&INDEX($L$4:$N$4,1,MATCH(MIN(L8:N8),L8:N8,0))&"="&MIN(L8:N8)&"; ","")&IF(AND(OR(C8="Governed Operations Zone",C8="Autonomous Operations Zone"),S8<4),"R3 evidence tier "&S8&"<4; ","")="","-",IF(AND(E8>=4,H8>=4),"R1 concentrated force; ","")&IF(AND(OR(C8="Governed Operations Zone",C8="Autonomous Operations Zone"),E8>=3,MIN(L8:N8)<=1),"R2 mandatory control "&INDEX($L$4:$N$4,1,MATCH(MIN(L8:N8),L8:N8,0))&"="&MIN(L8:N8)&"; ","")&IF(AND(OR(C8="Governed Operations Zone",C8="Autonomous Operations Zone"),S8<4),"R3 evidence tier "&S8&"<4; ",""))) -> R1 concentrated force; | AH8: =IF($A8="","",IF(MIN(IF(X8="Critical Orbit",1,IF(X8="Unstable Orbit",2,IF(X8="Edge Orbit",3,IF(X8="Controlled Orbit",4,5)))),IF(AF8="None",9,IF(AF8="Critical Orbit",1,IF(AF8="Unstable Orbit",2,IF(AF8="Edge Orbit",3,IF(AF8="Controlled Orbit",4,5))))))=1,"Critical Orbit",IF(MIN(IF(X8="Critical Orbit",1,IF(X8="Unstable Orbit",2,IF(X8="Edge Orbit",3,IF(X8="Controlled Orbit",4,5)))),IF(AF8="None",9,IF(AF8="Critical Orbit",1,IF(AF8="Unstable Orbit",2,IF(AF8="Edge Orbit",3,IF(AF8="Controlled Orbit",4,5))))))=2,"Unstable Orbit",IF(MIN(IF(X8="Critical Orbit",1,IF(X8="Unstable Orbit",2,IF(X8="Edge Orbit",3,IF(X8="Controlled Orbit",4,5)))),IF(AF8="None",9,IF(AF8="Critical Orbit",1,IF(AF8="Unstable Orbit",2,IF(AF8="Edge Orbit",3,IF(AF8="Controlled Orbit",4,5))))))=3,"Edge Orbit",IF(MIN(IF(X8="Critical Orbit",1,IF(X8="Unstable Orbit",2,IF(X8="Edge Orbit",3,IF(X8="Controlled Orbit",4,5)))),IF(AF8="None",9,IF(AF8="Critical Orbit",1,IF(AF8="Unstable Orbit",2,IF(AF8="Edge Orbit",3,IF(AF8="Controlled Orbit",4,5))))))=4,"Controlled Orbit","Stable Orbit"))))) -> Edge Orbit | AJ8: 2026-08-31
A9: Autonomous Production Remediation Agent | B9: Cloud / Infrastructure | C9: Autonomous Operations Zone | D9: Basic | E9: 5 | F9: 4 | G9: 5 | H9: 5 | I9: 4 | J9: 3 | K9: 5 | L9: 4 | M9: 4 | N9: 4 | O9: 3 | P9: 3 | Q9: 4 | R9: 2 | S9: 3 | T9: =IF($A9="","",IF(AND(MAX(L9:R9)>3,S9<3),"Warning: EGI >3 needs Tier 3+ evidence",IF(AND(C9="Autonomous Operations Zone",S9<4),"Warning: Autonomous zone needs Tier 4 evidence","OK"))) -> Warning: Autonomous zone needs Tier 4 evidence | U9: =IF($A9="","",IF($D9="Basic",SUM(E9:K9)/35*100,SUMPRODUCT(E9:K9,INDEX('Weighted Scoring'!$B$5:$H$13,MATCH($B9,'Weighted Scoring'!$A$5:$A$13,0),0))/SUMPRODUCT(5,INDEX('Weighted Scoring'!$B$5:$H$13,MATCH($B9,'Weighted Scoring'!$A$5:$A$13,0),0))*100)) -> 88.571429 | V9: =IF($A9="","",IF($D9="Basic",SUM(L9:R9)/35*100,SUMPRODUCT(L9:R9,INDEX('Weighted Scoring'!$I$5:$O$13,MATCH($B9,'Weighted Scoring'!$A$5:$A$13,0),0))/SUMPRODUCT(5,INDEX('Weighted Scoring'!$I$5:$O$13,MATCH($B9,'Weighted Scoring'!$A$5:$A$13,0),0))*100)) -> 68.571429 | W9: =IF($A9="","",V9-U9) -> -20 | X9: =IF($A9="","",IF(W9>=40,"Stable Orbit",IF(W9>=15,"Controlled Orbit",IF(W9>=-14,"Edge Orbit",IF(W9>=-39,"Unstable Orbit","Critical Orbit"))))) -> Unstable Orbit | Y9: =IF($A9="","",INDEX('Deployment Gates'!$C$5:$C$9,MATCH(AH9,'Deployment Gates'!$A$5:$A$9,0))) -> Do not expand; control uplift required | Z9: No | AA9: =IF($A9="","",IF(OR(AH9="Edge Orbit",AH9="Unstable Orbit",AH9="Critical Orbit",H9>=4,G9>=4,E9>=4,J9>=4),"Yes","No")) -> Yes | AB9: =IF($A9="","",IF(W9<0,"Yes","No")) -> Yes | AC9: =IF($A9="","",INDEX($L$4:$R$4,1,MATCH(MIN(L9:R9),L9:R9,0))&IF(COUNTIF(L9:R9,MIN(L9:R9))>1," (+"&(COUNTIF(L9:R9,MIN(L9:R9))-1)&" tied)","")) -> Assurance and Evaluation | AD9: =IF($A9="","",INDEX($E$4:$K$4,1,MATCH(MAX(E9:K9),E9:K9,0))&IF(COUNTIF(E9:K9,MAX(E9:K9))>1," (+"&(COUNTIF(E9:K9,MAX(E9:K9))-1)&" tied)","")) -> Decision Autonomy (+3 tied) | AE9: =IF($A9="","",INDEX('Control Uplift Planner'!$B$5:$B$11,MATCH(INDEX($L$4:$R$4,1,MATCH(MIN(L9:R9),L9:R9,0)),'Control Uplift Planner'!$A$5:$A$11,0))) -> Add scenario tests, red-team tests, runtime evaluation, drift monitoring, and outcome validation. | AF9: =IF($A9="","",IF(MIN(IF(AND(E9>=4,H9>=4),3,9),IF(AND(OR(C9="Governed Operations Zone",C9="Autonomous Operations Zone"),E9>=3),IF(MIN(L9:N9)=0,2,IF(MIN(L9:N9)=1,3,9)),9),IF(AND(OR(C9="Governed Operations Zone",C9="Autonomous Operations Zone"),S9<4),3,9))=9,"None",IF(MIN(IF(AND(E9>=4,H9>=4),3,9),IF(AND(OR(C9="Governed Operations Zone",C9="Autonomous Operations Zone"),E9>=3),IF(MIN(L9:N9)=0,2,IF(MIN(L9:N9)=1,3,9)),9),IF(AND(OR(C9="Governed Operations Zone",C9="Autonomous Operations Zone"),S9<4),3,9))=1,"Critical Orbit",IF(MIN(IF(AND(E9>=4,H9>=4),3,9),IF(AND(OR(C9="Governed Operations Zone",C9="Autonomous Operations Zone"),E9>=3),IF(MIN(L9:N9)=0,2,IF(MIN(L9:N9)=1,3,9)),9),IF(AND(OR(C9="Governed Operations Zone",C9="Autonomous Operations Zone"),S9<4),3,9))=2,"Unstable Orbit","Edge Orbit")))) -> Edge Orbit | AG9: =IF($A9="","",IF(IF(AND(E9>=4,H9>=4),"R1 concentrated force; ","")&IF(AND(OR(C9="Governed Operations Zone",C9="Autonomous Operations Zone"),E9>=3,MIN(L9:N9)<=1),"R2 mandatory control "&INDEX($L$4:$N$4,1,MATCH(MIN(L9:N9),L9:N9,0))&"="&MIN(L9:N9)&"; ","")&IF(AND(OR(C9="Governed Operations Zone",C9="Autonomous Operations Zone"),S9<4),"R3 evidence tier "&S9&"<4; ","")="","-",IF(AND(E9>=4,H9>=4),"R1 concentrated force; ","")&IF(AND(OR(C9="Governed Operations Zone",C9="Autonomous Operations Zone"),E9>=3,MIN(L9:N9)<=1),"R2 mandatory control "&INDEX($L$4:$N$4,1,MATCH(MIN(L9:N9),L9:N9,0))&"="&MIN(L9:N9)&"; ","")&IF(AND(OR(C9="Governed Operations Zone",C9="Autonomous Operations Zone"),S9<4),"R3 evidence tier "&S9&"<4; ",""))) -> R1 concentrated force; R3 evidence tier 3<4; | AH9: =IF($A9="","",IF(MIN(IF(X9="Critical Orbit",1,IF(X9="Unstable Orbit",2,IF(X9="Edge Orbit",3,IF(X9="Controlled Orbit",4,5)))),IF(AF9="None",9,IF(AF9="Critical Orbit",1,IF(AF9="Unstable Orbit",2,IF(AF9="Edge Orbit",3,IF(AF9="Controlled Orbit",4,5))))))=1,"Critical Orbit",IF(MIN(IF(X9="Critical Orbit",1,IF(X9="Unstable Orbit",2,IF(X9="Edge Orbit",3,IF(X9="Controlled Orbit",4,5)))),IF(AF9="None",9,IF(AF9="Critical Orbit",1,IF(AF9="Unstable Orbit",2,IF(AF9="Edge Orbit",3,IF(AF9="Controlled Orbit",4,5))))))=2,"Unstable Orbit",IF(MIN(IF(X9="Critical Orbit",1,IF(X9="Unstable Orbit",2,IF(X9="Edge Orbit",3,IF(X9="Controlled Orbit",4,5)))),IF(AF9="None",9,IF(AF9="Critical Orbit",1,IF(AF9="Unstable Orbit",2,IF(AF9="Edge Orbit",3,IF(AF9="Controlled Orbit",4,5))))))=3,"Edge Orbit",IF(MIN(IF(X9="Critical Orbit",1,IF(X9="Unstable Orbit",2,IF(X9="Edge Orbit",3,IF(X9="Controlled Orbit",4,5)))),IF(AF9="None",9,IF(AF9="Critical Orbit",1,IF(AF9="Unstable Orbit",2,IF(AF9="Edge Orbit",3,IF(AF9="Controlled Orbit",4,5))))))=4,"Controlled Orbit","Stable Orbit"))))) -> Unstable Orbit | AJ9: 2026-07-31
T10: =IF($A10="","",IF(AND(MAX(L10:R10)>3,S10<3),"Warning: EGI >3 needs Tier 3+ evidence",IF(AND(C10="Autonomous Operations Zone",S10<4),"Warning: Autonomous zone needs Tier 4 evidence","OK"))) | U10: =IF($A10="","",IF($D10="Basic",SUM(E10:K10)/35*100,SUMPRODUCT(E10:K10,INDEX('Weighted Scoring'!$B$5:$H$13,MATCH($B10,'Weighted Scoring'!$A$5:$A$13,0),0))/SUMPRODUCT(5,INDEX('Weighted Scoring'!$B$5:$H$13,MATCH($B10,'Weighted Scoring'!$A$5:$A$13,0),0))*100)) | V10: =IF($A10="","",IF($D10="Basic",SUM(L10:R10)/35*100,SUMPRODUCT(L10:R10,INDEX('Weighted Scoring'!$I$5:$O$13,MATCH($B10,'Weighted Scoring'!$A$5:$A$13,0),0))/SUMPRODUCT(5,INDEX('Weighted Scoring'!$I$5:$O$13,MATCH($B10,'Weighted Scoring'!$A$5:$A$13,0),0))*100)) | W10: =IF($A10="","",V10-U10) | X10: =IF($A10="","",IF(W10>=40,"Stable Orbit",IF(W10>=15,"Controlled Orbit",IF(W10>=-14,"Edge Orbit",IF(W10>=-39,"Unstable Orbit","Critical Orbit"))))) | Y10: =IF($A10="","",INDEX('Deployment Gates'!$C$5:$C$9,MATCH(AH10,'Deployment Gates'!$A$5:$A$9,0))) | AA10: =IF($A10="","",IF(OR(AH10="Edge Orbit",AH10="Unstable Orbit",AH10="Critical Orbit",H10>=4,G10>=4,E10>=4,J10>=4),"Yes","No")) | AB10: =IF($A10="","",IF(W10<0,"Yes","No")) | AC10: =IF($A10="","",INDEX($L$4:$R$4,1,MATCH(MIN(L10:R10),L10:R10,0))&IF(COUNTIF(L10:R10,MIN(L10:R10))>1," (+"&(COUNTIF(L10:R10,MIN(L10:R10))-1)&" tied)","")) | AD10: =IF($A10="","",INDEX($E$4:$K$4,1,MATCH(MAX(E10:K10),E10:K10,0))&IF(COUNTIF(E10:K10,MAX(E10:K10))>1," (+"&(COUNTIF(E10:K10,MAX(E10:K10))-1)&" tied)","")) | AE10: =IF($A10="","",INDEX('Control Uplift Planner'!$B$5:$B$11,MATCH(INDEX($L$4:$R$4,1,MATCH(MIN(L10:R10),L10:R10,0)),'Control Uplift Planner'!$A$5:$A$11,0))) | AF10: =IF($A10="","",IF(MIN(IF(AND(E10>=4,H10>=4),3,9),IF(AND(OR(C10="Governed Operations Zone",C10="Autonomous Operations Zone"),E10>=3),IF(MIN(L10:N10)=0,2,IF(MIN(L10:N10)=1,3,9)),9),IF(AND(OR(C10="Governed Operations Zone",C10="Autonomous Operations Zone"),S10<4),3,9))=9,"None",IF(MIN(IF(AND(E10>=4,H10>=4),3,9),IF(AND(OR(C10="Governed Operations Zone",C10="Autonomous Operations Zone"),E10>=3),IF(MIN(L10:N10)=0,2,IF(MIN(L10:N10)=1,3,9)),9),IF(AND(OR(C10="Governed Operations Zone",C10="Autonomous Operations Zone"),S10<4),3,9))=1,"Critical Orbit",IF(MIN(IF(AND(E10>=4,H10>=4),3,9),IF(AND(OR(C10="Governed Operations Zone",C10="Autonomous Operations Zone"),E10>=3),IF(MIN(L10:N10)=0,2,IF(MIN(L10:N10)=1,3,9)),9),IF(AND(OR(C10="Governed Operations Zone",C10="Autonomous Operations Zone"),S10<4),3,9))=2,"Unstable Orbit","Edge Orbit")))) | AG10: =IF($A10="","",IF(IF(AND(E10>=4,H10>=4),"R1 concentrated force; ","")&IF(AND(OR(C10="Governed Operations Zone",C10="Autonomous Operations Zone"),E10>=3,MIN(L10:N10)<=1),"R2 mandatory control "&INDEX($L$4:$N$4,1,MATCH(MIN(L10:N10),L10:N10,0))&"="&MIN(L10:N10)&"; ","")&IF(AND(OR(C10="Governed Operations Zone",C10="Autonomous Operations Zone"),S10<4),"R3 evidence tier "&S10&"<4; ","")="","-",IF(AND(E10>=4,H10>=4),"R1 concentrated force; ","")&IF(AND(OR(C10="Governed Operations Zone",C10="Autonomous Operations Zone"),E10>=3,MIN(L10:N10)<=1),"R2 mandatory control "&INDEX($L$4:$N$4,1,MATCH(MIN(L10:N10),L10:N10,0))&"="&MIN(L10:N10)&"; ","")&IF(AND(OR(C10="Governed Operations Zone",C10="Autonomous Operations Zone"),S10<4),"R3 evidence tier "&S10&"<4; ",""))) | AH10: =IF($A10="","",IF(MIN(IF(X10="Critical Orbit",1,IF(X10="Unstable Orbit",2,IF(X10="Edge Orbit",3,IF(X10="Controlled Orbit",4,5)))),IF(AF10="None",9,IF(AF10="Critical Orbit",1,IF(AF10="Unstable Orbit",2,IF(AF10="Edge Orbit",3,IF(AF10="Controlled Orbit",4,5))))))=1,"Critical Orbit",IF(MIN(IF(X10="Critical Orbit",1,IF(X10="Unstable Orbit",2,IF(X10="Edge Orbit",3,IF(X10="Controlled Orbit",4,5)))),IF(AF10="None",9,IF(AF10="Critical Orbit",1,IF(AF10="Unstable Orbit",2,IF(AF10="Edge Orbit",3,IF(AF10="Controlled Orbit",4,5))))))=2,"Unstable Orbit",IF(MIN(IF(X10="Critical Orbit",1,IF(X10="Unstable Orbit",2,IF(X10="Edge Orbit",3,IF(X10="Controlled Orbit",4,5)))),IF(AF10="None",9,IF(AF10="Critical Orbit",1,IF(AF10="Unstable Orbit",2,IF(AF10="Edge Orbit",3,IF(AF10="Controlled Orbit",4,5))))))=3,"Edge Orbit",IF(MIN(IF(X10="Critical Orbit",1,IF(X10="Unstable Orbit",2,IF(X10="Edge Orbit",3,IF(X10="Controlled Orbit",4,5)))),IF(AF10="None",9,IF(AF10="Critical Orbit",1,IF(AF10="Unstable Orbit",2,IF(AF10="Edge Orbit",3,IF(AF10="Controlled Orbit",4,5))))))=4,"Controlled Orbit","Stable Orbit")))))
T11: =IF($A11="","",IF(AND(MAX(L11:R11)>3,S11<3),"Warning: EGI >3 needs Tier 3+ evidence",IF(AND(C11="Autonomous Operations Zone",S11<4),"Warning: Autonomous zone needs Tier 4 evidence","OK"))) | U11: =IF($A11="","",IF($D11="Basic",SUM(E11:K11)/35*100,SUMPRODUCT(E11:K11,INDEX('Weighted Scoring'!$B$5:$H$13,MATCH($B11,'Weighted Scoring'!$A$5:$A$13,0),0))/SUMPRODUCT(5,INDEX('Weighted Scoring'!$B$5:$H$13,MATCH($B11,'Weighted Scoring'!$A$5:$A$13,0),0))*100)) | V11: =IF($A11="","",IF($D11="Basic",SUM(L11:R11)/35*100,SUMPRODUCT(L11:R11,INDEX('Weighted Scoring'!$I$5:$O$13,MATCH($B11,'Weighted Scoring'!$A$5:$A$13,0),0))/SUMPRODUCT(5,INDEX('Weighted Scoring'!$I$5:$O$13,MATCH($B11,'Weighted Scoring'!$A$5:$A$13,0),0))*100)) | W11: =IF($A11="","",V11-U11) | X11: =IF($A11="","",IF(W11>=40,"Stable Orbit",IF(W11>=15,"Controlled Orbit",IF(W11>=-14,"Edge Orbit",IF(W11>=-39,"Unstable Orbit","Critical Orbit"))))) | Y11: =IF($A11="","",INDEX('Deployment Gates'!$C$5:$C$9,MATCH(AH11,'Deployment Gates'!$A$5:$A$9,0))) | AA11: =IF($A11="","",IF(OR(AH11="Edge Orbit",AH11="Unstable Orbit",AH11="Critical Orbit",H11>=4,G11>=4,E11>=4,J11>=4),"Yes","No")) | AB11: =IF($A11="","",IF(W11<0,"Yes","No")) | AC11: =IF($A11="","",INDEX($L$4:$R$4,1,MATCH(MIN(L11:R11),L11:R11,0))&IF(COUNTIF(L11:R11,MIN(L11:R11))>1," (+"&(COUNTIF(L11:R11,MIN(L11:R11))-1)&" tied)","")) | AD11: =IF($A11="","",INDEX($E$4:$K$4,1,MATCH(MAX(E11:K11),E11:K11,0))&IF(COUNTIF(E11:K11,MAX(E11:K11))>1," (+"&(COUNTIF(E11:K11,MAX(E11:K11))-1)&" tied)","")) | AE11: =IF($A11="","",INDEX('Control Uplift Planner'!$B$5:$B$11,MATCH(INDEX($L$4:$R$4,1,MATCH(MIN(L11:R11),L11:R11,0)),'Control Uplift Planner'!$A$5:$A$11,0))) | AF11: =IF($A11="","",IF(MIN(IF(AND(E11>=4,H11>=4),3,9),IF(AND(OR(C11="Governed Operations Zone",C11="Autonomous Operations Zone"),E11>=3),IF(MIN(L11:N11)=0,2,IF(MIN(L11:N11)=1,3,9)),9),IF(AND(OR(C11="Governed Operations Zone",C11="Autonomous Operations Zone"),S11<4),3,9))=9,"None",IF(MIN(IF(AND(E11>=4,H11>=4),3,9),IF(AND(OR(C11="Governed Operations Zone",C11="Autonomous Operations Zone"),E11>=3),IF(MIN(L11:N11)=0,2,IF(MIN(L11:N11)=1,3,9)),9),IF(AND(OR(C11="Governed Operations Zone",C11="Autonomous Operations Zone"),S11<4),3,9))=1,"Critical Orbit",IF(MIN(IF(AND(E11>=4,H11>=4),3,9),IF(AND(OR(C11="Governed Operations Zone",C11="Autonomous Operations Zone"),E11>=3),IF(MIN(L11:N11)=0,2,IF(MIN(L11:N11)=1,3,9)),9),IF(AND(OR(C11="Governed Operations Zone",C11="Autonomous Operations Zone"),S11<4),3,9))=2,"Unstable Orbit","Edge Orbit")))) | AG11: =IF($A11="","",IF(IF(AND(E11>=4,H11>=4),"R1 concentrated force; ","")&IF(AND(OR(C11="Governed Operations Zone",C11="Autonomous Operations Zone"),E11>=3,MIN(L11:N11)<=1),"R2 mandatory control "&INDEX($L$4:$N$4,1,MATCH(MIN(L11:N11),L11:N11,0))&"="&MIN(L11:N11)&"; ","")&IF(AND(OR(C11="Governed Operations Zone",C11="Autonomous Operations Zone"),S11<4),"R3 evidence tier "&S11&"<4; ","")="","-",IF(AND(E11>=4,H11>=4),"R1 concentrated force; ","")&IF(AND(OR(C11="Governed Operations Zone",C11="Autonomous Operations Zone"),E11>=3,MIN(L11:N11)<=1),"R2 mandatory control "&INDEX($L$4:$N$4,1,MATCH(MIN(L11:N11),L11:N11,0))&"="&MIN(L11:N11)&"; ","")&IF(AND(OR(C11="Governed Operations Zone",C11="Autonomous Operations Zone"),S11<4),"R3 evidence tier "&S11&"<4; ",""))) | AH11: =IF($A11="","",IF(MIN(IF(X11="Critical Orbit",1,IF(X11="Unstable Orbit",2,IF(X11="Edge Orbit",3,IF(X11="Controlled Orbit",4,5)))),IF(AF11="None",9,IF(AF11="Critical Orbit",1,IF(AF11="Unstable Orbit",2,IF(AF11="Edge Orbit",3,IF(AF11="Controlled Orbit",4,5))))))=1,"Critical Orbit",IF(MIN(IF(X11="Critical Orbit",1,IF(X11="Unstable Orbit",2,IF(X11="Edge Orbit",3,IF(X11="Controlled Orbit",4,5)))),IF(AF11="None",9,IF(AF11="Critical Orbit",1,IF(AF11="Unstable Orbit",2,IF(AF11="Edge Orbit",3,IF(AF11="Controlled Orbit",4,5))))))=2,"Unstable Orbit",IF(MIN(IF(X11="Critical Orbit",1,IF(X11="Unstable Orbit",2,IF(X11="Edge Orbit",3,IF(X11="Controlled Orbit",4,5)))),IF(AF11="None",9,IF(AF11="Critical Orbit",1,IF(AF11="Unstable Orbit",2,IF(AF11="Edge Orbit",3,IF(AF11="Controlled Orbit",4,5))))))=3,"Edge Orbit",IF(MIN(IF(X11="Critical Orbit",1,IF(X11="Unstable Orbit",2,IF(X11="Edge Orbit",3,IF(X11="Controlled Orbit",4,5)))),IF(AF11="None",9,IF(AF11="Critical Orbit",1,IF(AF11="Unstable Orbit",2,IF(AF11="Edge Orbit",3,IF(AF11="Controlled Orbit",4,5))))))=4,"Controlled Orbit","Stable Orbit")))))
T12: =IF($A12="","",IF(AND(MAX(L12:R12)>3,S12<3),"Warning: EGI >3 needs Tier 3+ evidence",IF(AND(C12="Autonomous Operations Zone",S12<4),"Warning: Autonomous zone needs Tier 4 evidence","OK"))) | U12: =IF($A12="","",IF($D12="Basic",SUM(E12:K12)/35*100,SUMPRODUCT(E12:K12,INDEX('Weighted Scoring'!$B$5:$H$13,MATCH($B12,'Weighted Scoring'!$A$5:$A$13,0),0))/SUMPRODUCT(5,INDEX('Weighted Scoring'!$B$5:$H$13,MATCH($B12,'Weighted Scoring'!$A$5:$A$13,0),0))*100)) | V12: =IF($A12="","",IF($D12="Basic",SUM(L12:R12)/35*100,SUMPRODUCT(L12:R12,INDEX('Weighted Scoring'!$I$5:$O$13,MATCH($B12,'Weighted Scoring'!$A$5:$A$13,0),0))/SUMPRODUCT(5,INDEX('Weighted Scoring'!$I$5:$O$13,MATCH($B12,'Weighted Scoring'!$A$5:$A$13,0),0))*100)) | W12: =IF($A12="","",V12-U12) | X12: =IF($A12="","",IF(W12>=40,"Stable Orbit",IF(W12>=15,"Controlled Orbit",IF(W12>=-14,"Edge Orbit",IF(W12>=-39,"Unstable Orbit","Critical Orbit"))))) | Y12: =IF($A12="","",INDEX('Deployment Gates'!$C$5:$C$9,MATCH(AH12,'Deployment Gates'!$A$5:$A$9,0))) | AA12: =IF($A12="","",IF(OR(AH12="Edge Orbit",AH12="Unstable Orbit",AH12="Critical Orbit",H12>=4,G12>=4,E12>=4,J12>=4),"Yes","No")) | AB12: =IF($A12="","",IF(W12<0,"Yes","No")) | AC12: =IF($A12="","",INDEX($L$4:$R$4,1,MATCH(MIN(L12:R12),L12:R12,0))&IF(COUNTIF(L12:R12,MIN(L12:R12))>1," (+"&(COUNTIF(L12:R12,MIN(L12:R12))-1)&" tied)","")) | AD12: =IF($A12="","",INDEX($E$4:$K$4,1,MATCH(MAX(E12:K12),E12:K12,0))&IF(COUNTIF(E12:K12,MAX(E12:K12))>1," (+"&(COUNTIF(E12:K12,MAX(E12:K12))-1)&" tied)","")) | AE12: =IF($A12="","",INDEX('Control Uplift Planner'!$B$5:$B$11,MATCH(INDEX($L$4:$R$4,1,MATCH(MIN(L12:R12),L12:R12,0)),'Control Uplift Planner'!$A$5:$A$11,0))) | AF12: =IF($A12="","",IF(MIN(IF(AND(E12>=4,H12>=4),3,9),IF(AND(OR(C12="Governed Operations Zone",C12="Autonomous Operations Zone"),E12>=3),IF(MIN(L12:N12)=0,2,IF(MIN(L12:N12)=1,3,9)),9),IF(AND(OR(C12="Governed Operations Zone",C12="Autonomous Operations Zone"),S12<4),3,9))=9,"None",IF(MIN(IF(AND(E12>=4,H12>=4),3,9),IF(AND(OR(C12="Governed Operations Zone",C12="Autonomous Operations Zone"),E12>=3),IF(MIN(L12:N12)=0,2,IF(MIN(L12:N12)=1,3,9)),9),IF(AND(OR(C12="Governed Operations Zone",C12="Autonomous Operations Zone"),S12<4),3,9))=1,"Critical Orbit",IF(MIN(IF(AND(E12>=4,H12>=4),3,9),IF(AND(OR(C12="Governed Operations Zone",C12="Autonomous Operations Zone"),E12>=3),IF(MIN(L12:N12)=0,2,IF(MIN(L12:N12)=1,3,9)),9),IF(AND(OR(C12="Governed Operations Zone",C12="Autonomous Operations Zone"),S12<4),3,9))=2,"Unstable Orbit","Edge Orbit")))) | AG12: =IF($A12="","",IF(IF(AND(E12>=4,H12>=4),"R1 concentrated force; ","")&IF(AND(OR(C12="Governed Operations Zone",C12="Autonomous Operations Zone"),E12>=3,MIN(L12:N12)<=1),"R2 mandatory control "&INDEX($L$4:$N$4,1,MATCH(MIN(L12:N12),L12:N12,0))&"="&MIN(L12:N12)&"; ","")&IF(AND(OR(C12="Governed Operations Zone",C12="Autonomous Operations Zone"),S12<4),"R3 evidence tier "&S12&"<4; ","")="","-",IF(AND(E12>=4,H12>=4),"R1 concentrated force; ","")&IF(AND(OR(C12="Governed Operations Zone",C12="Autonomous Operations Zone"),E12>=3,MIN(L12:N12)<=1),"R2 mandatory control "&INDEX($L$4:$N$4,1,MATCH(MIN(L12:N12),L12:N12,0))&"="&MIN(L12:N12)&"; ","")&IF(AND(OR(C12="Governed Operations Zone",C12="Autonomous Operations Zone"),S12<4),"R3 evidence tier "&S12&"<4; ",""))) | AH12: =IF($A12="","",IF(MIN(IF(X12="Critical Orbit",1,IF(X12="Unstable Orbit",2,IF(X12="Edge Orbit",3,IF(X12="Controlled Orbit",4,5)))),IF(AF12="None",9,IF(AF12="Critical Orbit",1,IF(AF12="Unstable Orbit",2,IF(AF12="Edge Orbit",3,IF(AF12="Controlled Orbit",4,5))))))=1,"Critical Orbit",IF(MIN(IF(X12="Critical Orbit",1,IF(X12="Unstable Orbit",2,IF(X12="Edge Orbit",3,IF(X12="Controlled Orbit",4,5)))),IF(AF12="None",9,IF(AF12="Critical Orbit",1,IF(AF12="Unstable Orbit",2,IF(AF12="Edge Orbit",3,IF(AF12="Controlled Orbit",4,5))))))=2,"Unstable Orbit",IF(MIN(IF(X12="Critical Orbit",1,IF(X12="Unstable Orbit",2,IF(X12="Edge Orbit",3,IF(X12="Controlled Orbit",4,5)))),IF(AF12="None",9,IF(AF12="Critical Orbit",1,IF(AF12="Unstable Orbit",2,IF(AF12="Edge Orbit",3,IF(AF12="Controlled Orbit",4,5))))))=3,"Edge Orbit",IF(MIN(IF(X12="Critical Orbit",1,IF(X12="Unstable Orbit",2,IF(X12="Edge Orbit",3,IF(X12="Controlled Orbit",4,5)))),IF(AF12="None",9,IF(AF12="Critical Orbit",1,IF(AF12="Unstable Orbit",2,IF(AF12="Edge Orbit",3,IF(AF12="Controlled Orbit",4,5))))))=4,"Controlled Orbit","Stable Orbit")))))
T13: =IF($A13="","",IF(AND(MAX(L13:R13)>3,S13<3),"Warning: EGI >3 needs Tier 3+ evidence",IF(AND(C13="Autonomous Operations Zone",S13<4),"Warning: Autonomous zone needs Tier 4 evidence","OK"))) | U13: =IF($A13="","",IF($D13="Basic",SUM(E13:K13)/35*100,SUMPRODUCT(E13:K13,INDEX('Weighted Scoring'!$B$5:$H$13,MATCH($B13,'Weighted Scoring'!$A$5:$A$13,0),0))/SUMPRODUCT(5,INDEX('Weighted Scoring'!$B$5:$H$13,MATCH($B13,'Weighted Scoring'!$A$5:$A$13,0),0))*100)) | V13: =IF($A13="","",IF($D13="Basic",SUM(L13:R13)/35*100,SUMPRODUCT(L13:R13,INDEX('Weighted Scoring'!$I$5:$O$13,MATCH($B13,'Weighted Scoring'!$A$5:$A$13,0),0))/SUMPRODUCT(5,INDEX('Weighted Scoring'!$I$5:$O$13,MATCH($B13,'Weighted Scoring'!$A$5:$A$13,0),0))*100)) | W13: =IF($A13="","",V13-U13) | X13: =IF($A13="","",IF(W13>=40,"Stable Orbit",IF(W13>=15,"Controlled Orbit",IF(W13>=-14,"Edge Orbit",IF(W13>=-39,"Unstable Orbit","Critical Orbit"))))) | Y13: =IF($A13="","",INDEX('Deployment Gates'!$C$5:$C$9,MATCH(AH13,'Deployment Gates'!$A$5:$A$9,0))) | AA13: =IF($A13="","",IF(OR(AH13="Edge Orbit",AH13="Unstable Orbit",AH13="Critical Orbit",H13>=4,G13>=4,E13>=4,J13>=4),"Yes","No")) | AB13: =IF($A13="","",IF(W13<0,"Yes","No")) | AC13: =IF($A13="","",INDEX($L$4:$R$4,1,MATCH(MIN(L13:R13),L13:R13,0))&IF(COUNTIF(L13:R13,MIN(L13:R13))>1," (+"&(COUNTIF(L13:R13,MIN(L13:R13))-1)&" tied)","")) | AD13: =IF($A13="","",INDEX($E$4:$K$4,1,MATCH(MAX(E13:K13),E13:K13,0))&IF(COUNTIF(E13:K13,MAX(E13:K13))>1," (+"&(COUNTIF(E13:K13,MAX(E13:K13))-1)&" tied)","")) | AE13: =IF($A13="","",INDEX('Control Uplift Planner'!$B$5:$B$11,MATCH(INDEX($L$4:$R$4,1,MATCH(MIN(L13:R13),L13:R13,0)),'Control Uplift Planner'!$A$5:$A$11,0))) | AF13: =IF($A13="","",IF(MIN(IF(AND(E13>=4,H13>=4),3,9),IF(AND(OR(C13="Governed Operations Zone",C13="Autonomous Operations Zone"),E13>=3),IF(MIN(L13:N13)=0,2,IF(MIN(L13:N13)=1,3,9)),9),IF(AND(OR(C13="Governed Operations Zone",C13="Autonomous Operations Zone"),S13<4),3,9))=9,"None",IF(MIN(IF(AND(E13>=4,H13>=4),3,9),IF(AND(OR(C13="Governed Operations Zone",C13="Autonomous Operations Zone"),E13>=3),IF(MIN(L13:N13)=0,2,IF(MIN(L13:N13)=1,3,9)),9),IF(AND(OR(C13="Governed Operations Zone",C13="Autonomous Operations Zone"),S13<4),3,9))=1,"Critical Orbit",IF(MIN(IF(AND(E13>=4,H13>=4),3,9),IF(AND(OR(C13="Governed Operations Zone",C13="Autonomous Operations Zone"),E13>=3),IF(MIN(L13:N13)=0,2,IF(MIN(L13:N13)=1,3,9)),9),IF(AND(OR(C13="Governed Operations Zone",C13="Autonomous Operations Zone"),S13<4),3,9))=2,"Unstable Orbit","Edge Orbit")))) | AG13: =IF($A13="","",IF(IF(AND(E13>=4,H13>=4),"R1 concentrated force; ","")&IF(AND(OR(C13="Governed Operations Zone",C13="Autonomous Operations Zone"),E13>=3,MIN(L13:N13)<=1),"R2 mandatory control "&INDEX($L$4:$N$4,1,MATCH(MIN(L13:N13),L13:N13,0))&"="&MIN(L13:N13)&"; ","")&IF(AND(OR(C13="Governed Operations Zone",C13="Autonomous Operations Zone"),S13<4),"R3 evidence tier "&S13&"<4; ","")="","-",IF(AND(E13>=4,H13>=4),"R1 concentrated force; ","")&IF(AND(OR(C13="Governed Operations Zone",C13="Autonomous Operations Zone"),E13>=3,MIN(L13:N13)<=1),"R2 mandatory control "&INDEX($L$4:$N$4,1,MATCH(MIN(L13:N13),L13:N13,0))&"="&MIN(L13:N13)&"; ","")&IF(AND(OR(C13="Governed Operations Zone",C13="Autonomous Operations Zone"),S13<4),"R3 evidence tier "&S13&"<4; ",""))) | AH13: =IF($A13="","",IF(MIN(IF(X13="Critical Orbit",1,IF(X13="Unstable Orbit",2,IF(X13="Edge Orbit",3,IF(X13="Controlled Orbit",4,5)))),IF(AF13="None",9,IF(AF13="Critical Orbit",1,IF(AF13="Unstable Orbit",2,IF(AF13="Edge Orbit",3,IF(AF13="Controlled Orbit",4,5))))))=1,"Critical Orbit",IF(MIN(IF(X13="Critical Orbit",1,IF(X13="Unstable Orbit",2,IF(X13="Edge Orbit",3,IF(X13="Controlled Orbit",4,5)))),IF(AF13="None",9,IF(AF13="Critical Orbit",1,IF(AF13="Unstable Orbit",2,IF(AF13="Edge Orbit",3,IF(AF13="Controlled Orbit",4,5))))))=2,"Unstable Orbit",IF(MIN(IF(X13="Critical Orbit",1,IF(X13="Unstable Orbit",2,IF(X13="Edge Orbit",3,IF(X13="Controlled Orbit",4,5)))),IF(AF13="None",9,IF(AF13="Critical Orbit",1,IF(AF13="Unstable Orbit",2,IF(AF13="Edge Orbit",3,IF(AF13="Controlled Orbit",4,5))))))=3,"Edge Orbit",IF(MIN(IF(X13="Critical Orbit",1,IF(X13="Unstable Orbit",2,IF(X13="Edge Orbit",3,IF(X13="Controlled Orbit",4,5)))),IF(AF13="None",9,IF(AF13="Critical Orbit",1,IF(AF13="Unstable Orbit",2,IF(AF13="Edge Orbit",3,IF(AF13="Controlled Orbit",4,5))))))=4,"Controlled Orbit","Stable Orbit")))))
T14: =IF($A14="","",IF(AND(MAX(L14:R14)>3,S14<3),"Warning: EGI >3 needs Tier 3+ evidence",IF(AND(C14="Autonomous Operations Zone",S14<4),"Warning: Autonomous zone needs Tier 4 evidence","OK"))) | U14: =IF($A14="","",IF($D14="Basic",SUM(E14:K14)/35*100,SUMPRODUCT(E14:K14,INDEX('Weighted Scoring'!$B$5:$H$13,MATCH($B14,'Weighted Scoring'!$A$5:$A$13,0),0))/SUMPRODUCT(5,INDEX('Weighted Scoring'!$B$5:$H$13,MATCH($B14,'Weighted Scoring'!$A$5:$A$13,0),0))*100)) | V14: =IF($A14="","",IF($D14="Basic",SUM(L14:R14)/35*100,SUMPRODUCT(L14:R14,INDEX('Weighted Scoring'!$I$5:$O$13,MATCH($B14,'Weighted Scoring'!$A$5:$A$13,0),0))/SUMPRODUCT(5,INDEX('Weighted Scoring'!$I$5:$O$13,MATCH($B14,'Weighted Scoring'!$A$5:$A$13,0),0))*100)) | W14: =IF($A14="","",V14-U14) | X14: =IF($A14="","",IF(W14>=40,"Stable Orbit",IF(W14>=15,"Controlled Orbit",IF(W14>=-14,"Edge Orbit",IF(W14>=-39,"Unstable Orbit","Critical Orbit"))))) | Y14: =IF($A14="","",INDEX('Deployment Gates'!$C$5:$C$9,MATCH(AH14,'Deployment Gates'!$A$5:$A$9,0))) | AA14: =IF($A14="","",IF(OR(AH14="Edge Orbit",AH14="Unstable Orbit",AH14="Critical Orbit",H14>=4,G14>=4,E14>=4,J14>=4),"Yes","No")) | AB14: =IF($A14="","",IF(W14<0,"Yes","No")) | AC14: =IF($A14="","",INDEX($L$4:$R$4,1,MATCH(MIN(L14:R14),L14:R14,0))&IF(COUNTIF(L14:R14,MIN(L14:R14))>1," (+"&(COUNTIF(L14:R14,MIN(L14:R14))-1)&" tied)","")) | AD14: =IF($A14="","",INDEX($E$4:$K$4,1,MATCH(MAX(E14:K14),E14:K14,0))&IF(COUNTIF(E14:K14,MAX(E14:K14))>1," (+"&(COUNTIF(E14:K14,MAX(E14:K14))-1)&" tied)","")) | AE14: =IF($A14="","",INDEX('Control Uplift Planner'!$B$5:$B$11,MATCH(INDEX($L$4:$R$4,1,MATCH(MIN(L14:R14),L14:R14,0)),'Control Uplift Planner'!$A$5:$A$11,0))) | AF14: =IF($A14="","",IF(MIN(IF(AND(E14>=4,H14>=4),3,9),IF(AND(OR(C14="Governed Operations Zone",C14="Autonomous Operations Zone"),E14>=3),IF(MIN(L14:N14)=0,2,IF(MIN(L14:N14)=1,3,9)),9),IF(AND(OR(C14="Governed Operations Zone",C14="Autonomous Operations Zone"),S14<4),3,9))=9,"None",IF(MIN(IF(AND(E14>=4,H14>=4),3,9),IF(AND(OR(C14="Governed Operations Zone",C14="Autonomous Operations Zone"),E14>=3),IF(MIN(L14:N14)=0,2,IF(MIN(L14:N14)=1,3,9)),9),IF(AND(OR(C14="Governed Operations Zone",C14="Autonomous Operations Zone"),S14<4),3,9))=1,"Critical Orbit",IF(MIN(IF(AND(E14>=4,H14>=4),3,9),IF(AND(OR(C14="Governed Operations Zone",C14="Autonomous Operations Zone"),E14>=3),IF(MIN(L14:N14)=0,2,IF(MIN(L14:N14)=1,3,9)),9),IF(AND(OR(C14="Governed Operations Zone",C14="Autonomous Operations Zone"),S14<4),3,9))=2,"Unstable Orbit","Edge Orbit")))) | AG14: =IF($A14="","",IF(IF(AND(E14>=4,H14>=4),"R1 concentrated force; ","")&IF(AND(OR(C14="Governed Operations Zone",C14="Autonomous Operations Zone"),E14>=3,MIN(L14:N14)<=1),"R2 mandatory control "&INDEX($L$4:$N$4,1,MATCH(MIN(L14:N14),L14:N14,0))&"="&MIN(L14:N14)&"; ","")&IF(AND(OR(C14="Governed Operations Zone",C14="Autonomous Operations Zone"),S14<4),"R3 evidence tier "&S14&"<4; ","")="","-",IF(AND(E14>=4,H14>=4),"R1 concentrated force; ","")&IF(AND(OR(C14="Governed Operations Zone",C14="Autonomous Operations Zone"),E14>=3,MIN(L14:N14)<=1),"R2 mandatory control "&INDEX($L$4:$N$4,1,MATCH(MIN(L14:N14),L14:N14,0))&"="&MIN(L14:N14)&"; ","")&IF(AND(OR(C14="Governed Operations Zone",C14="Autonomous Operations Zone"),S14<4),"R3 evidence tier "&S14&"<4; ",""))) | AH14: =IF($A14="","",IF(MIN(IF(X14="Critical Orbit",1,IF(X14="Unstable Orbit",2,IF(X14="Edge Orbit",3,IF(X14="Controlled Orbit",4,5)))),IF(AF14="None",9,IF(AF14="Critical Orbit",1,IF(AF14="Unstable Orbit",2,IF(AF14="Edge Orbit",3,IF(AF14="Controlled Orbit",4,5))))))=1,"Critical Orbit",IF(MIN(IF(X14="Critical Orbit",1,IF(X14="Unstable Orbit",2,IF(X14="Edge Orbit",3,IF(X14="Controlled Orbit",4,5)))),IF(AF14="None",9,IF(AF14="Critical Orbit",1,IF(AF14="Unstable Orbit",2,IF(AF14="Edge Orbit",3,IF(AF14="Controlled Orbit",4,5))))))=2,"Unstable Orbit",IF(MIN(IF(X14="Critical Orbit",1,IF(X14="Unstable Orbit",2,IF(X14="Edge Orbit",3,IF(X14="Controlled Orbit",4,5)))),IF(AF14="None",9,IF(AF14="Critical Orbit",1,IF(AF14="Unstable Orbit",2,IF(AF14="Edge Orbit",3,IF(AF14="Controlled Orbit",4,5))))))=3,"Edge Orbit",IF(MIN(IF(X14="Critical Orbit",1,IF(X14="Unstable Orbit",2,IF(X14="Edge Orbit",3,IF(X14="Controlled Orbit",4,5)))),IF(AF14="None",9,IF(AF14="Critical Orbit",1,IF(AF14="Unstable Orbit",2,IF(AF14="Edge Orbit",3,IF(AF14="Controlled Orbit",4,5))))))=4,"Controlled Orbit","Stable Orbit")))))
T15: =IF($A15="","",IF(AND(MAX(L15:R15)>3,S15<3),"Warning: EGI >3 needs Tier 3+ evidence",IF(AND(C15="Autonomous Operations Zone",S15<4),"Warning: Autonomous zone needs Tier 4 evidence","OK"))) | U15: =IF($A15="","",IF($D15="Basic",SUM(E15:K15)/35*100,SUMPRODUCT(E15:K15,INDEX('Weighted Scoring'!$B$5:$H$13,MATCH($B15,'Weighted Scoring'!$A$5:$A$13,0),0))/SUMPRODUCT(5,INDEX('Weighted Scoring'!$B$5:$H$13,MATCH($B15,'Weighted Scoring'!$A$5:$A$13,0),0))*100)) | V15: =IF($A15="","",IF($D15="Basic",SUM(L15:R15)/35*100,SUMPRODUCT(L15:R15,INDEX('Weighted Scoring'!$I$5:$O$13,MATCH($B15,'Weighted Scoring'!$A$5:$A$13,0),0))/SUMPRODUCT(5,INDEX('Weighted Scoring'!$I$5:$O$13,MATCH($B15,'Weighted Scoring'!$A$5:$A$13,0),0))*100)) | W15: =IF($A15="","",V15-U15) | X15: =IF($A15="","",IF(W15>=40,"Stable Orbit",IF(W15>=15,"Controlled Orbit",IF(W15>=-14,"Edge Orbit",IF(W15>=-39,"Unstable Orbit","Critical Orbit"))))) | Y15: =IF($A15="","",INDEX('Deployment Gates'!$C$5:$C$9,MATCH(AH15,'Deployment Gates'!$A$5:$A$9,0))) | AA15: =IF($A15="","",IF(OR(AH15="Edge Orbit",AH15="Unstable Orbit",AH15="Critical Orbit",H15>=4,G15>=4,E15>=4,J15>=4),"Yes","No")) | AB15: =IF($A15="","",IF(W15<0,"Yes","No")) | AC15: =IF($A15="","",INDEX($L$4:$R$4,1,MATCH(MIN(L15:R15),L15:R15,0))&IF(COUNTIF(L15:R15,MIN(L15:R15))>1," (+"&(COUNTIF(L15:R15,MIN(L15:R15))-1)&" tied)","")) | AD15: =IF($A15="","",INDEX($E$4:$K$4,1,MATCH(MAX(E15:K15),E15:K15,0))&IF(COUNTIF(E15:K15,MAX(E15:K15))>1," (+"&(COUNTIF(E15:K15,MAX(E15:K15))-1)&" tied)","")) | AE15: =IF($A15="","",INDEX('Control Uplift Planner'!$B$5:$B$11,MATCH(INDEX($L$4:$R$4,1,MATCH(MIN(L15:R15),L15:R15,0)),'Control Uplift Planner'!$A$5:$A$11,0))) | AF15: =IF($A15="","",IF(MIN(IF(AND(E15>=4,H15>=4),3,9),IF(AND(OR(C15="Governed Operations Zone",C15="Autonomous Operations Zone"),E15>=3),IF(MIN(L15:N15)=0,2,IF(MIN(L15:N15)=1,3,9)),9),IF(AND(OR(C15="Governed Operations Zone",C15="Autonomous Operations Zone"),S15<4),3,9))=9,"None",IF(MIN(IF(AND(E15>=4,H15>=4),3,9),IF(AND(OR(C15="Governed Operations Zone",C15="Autonomous Operations Zone"),E15>=3),IF(MIN(L15:N15)=0,2,IF(MIN(L15:N15)=1,3,9)),9),IF(AND(OR(C15="Governed Operations Zone",C15="Autonomous Operations Zone"),S15<4),3,9))=1,"Critical Orbit",IF(MIN(IF(AND(E15>=4,H15>=4),3,9),IF(AND(OR(C15="Governed Operations Zone",C15="Autonomous Operations Zone"),E15>=3),IF(MIN(L15:N15)=0,2,IF(MIN(L15:N15)=1,3,9)),9),IF(AND(OR(C15="Governed Operations Zone",C15="Autonomous Operations Zone"),S15<4),3,9))=2,"Unstable Orbit","Edge Orbit")))) | AG15: =IF($A15="","",IF(IF(AND(E15>=4,H15>=4),"R1 concentrated force; ","")&IF(AND(OR(C15="Governed Operations Zone",C15="Autonomous Operations Zone"),E15>=3,MIN(L15:N15)<=1),"R2 mandatory control "&INDEX($L$4:$N$4,1,MATCH(MIN(L15:N15),L15:N15,0))&"="&MIN(L15:N15)&"; ","")&IF(AND(OR(C15="Governed Operations Zone",C15="Autonomous Operations Zone"),S15<4),"R3 evidence tier "&S15&"<4; ","")="","-",IF(AND(E15>=4,H15>=4),"R1 concentrated force; ","")&IF(AND(OR(C15="Governed Operations Zone",C15="Autonomous Operations Zone"),E15>=3,MIN(L15:N15)<=1),"R2 mandatory control "&INDEX($L$4:$N$4,1,MATCH(MIN(L15:N15),L15:N15,0))&"="&MIN(L15:N15)&"; ","")&IF(AND(OR(C15="Governed Operations Zone",C15="Autonomous Operations Zone"),S15<4),"R3 evidence tier "&S15&"<4; ",""))) | AH15: =IF($A15="","",IF(MIN(IF(X15="Critical Orbit",1,IF(X15="Unstable Orbit",2,IF(X15="Edge Orbit",3,IF(X15="Controlled Orbit",4,5)))),IF(AF15="None",9,IF(AF15="Critical Orbit",1,IF(AF15="Unstable Orbit",2,IF(AF15="Edge Orbit",3,IF(AF15="Controlled Orbit",4,5))))))=1,"Critical Orbit",IF(MIN(IF(X15="Critical Orbit",1,IF(X15="Unstable Orbit",2,IF(X15="Edge Orbit",3,IF(X15="Controlled Orbit",4,5)))),IF(AF15="None",9,IF(AF15="Critical Orbit",1,IF(AF15="Unstable Orbit",2,IF(AF15="Edge Orbit",3,IF(AF15="Controlled Orbit",4,5))))))=2,"Unstable Orbit",IF(MIN(IF(X15="Critical Orbit",1,IF(X15="Unstable Orbit",2,IF(X15="Edge Orbit",3,IF(X15="Controlled Orbit",4,5)))),IF(AF15="None",9,IF(AF15="Critical Orbit",1,IF(AF15="Unstable Orbit",2,IF(AF15="Edge Orbit",3,IF(AF15="Controlled Orbit",4,5))))))=3,"Edge Orbit",IF(MIN(IF(X15="Critical Orbit",1,IF(X15="Unstable Orbit",2,IF(X15="Edge Orbit",3,IF(X15="Controlled Orbit",4,5)))),IF(AF15="None",9,IF(AF15="Critical Orbit",1,IF(AF15="Unstable Orbit",2,IF(AF15="Edge Orbit",3,IF(AF15="Controlled Orbit",4,5))))))=4,"Controlled Orbit","Stable Orbit")))))
